<?xml version="1.0" ?>
<robot name="block">
  <link name="world"/>
  <link name="base_link">
    <visual>
      <geometry>
        <box size="100 100 0.05"/>
      </geometry>
      <origin xyz="0 0 0"/>
      <material name="green">
        <color rgba="0 0.8 .8 1"/>
      </material>
    </visual>
    <collision>
      <geometry>
        <box size="100 100 0.05"/>
      </geometry>
      <origin xyz="0 0 0"/>
    </collision>
    <inertial>
      <mass value="100"/>
      <origin xyz="0 0 0"/>
      <inertia ixx="1.0" ixy="0.0" ixz="0.0" iyy="1.0" iyz="0.0" izz="1.0"/>
    </inertial>
  </link>
  <link name="cuboid">
    <visual>
      <geometry>
        <box size="1 1 0.1"/>
      </geometry>
      <origin xyz="0 0 0"/>
      <material name="green">
        <color rgba="0 0.8 .8 1"/>
      </material>
    </visual>
    <collision>
      <geometry>
        <box size="1 1 0.1"/>
      </geometry>
      <origin xyz="0 0 0"/>
    </collision>
    <inertial>
      <mass value="1"/>
      <inertia ixx="1.0" ixy="0.0" ixz="0.0" iyy="1.0" iyz="0.0" izz="1.0"/>
    </inertial>
  </link>

  <link name="cuboid_y">
     <inertial>
      <mass value="1"/>
      <inertia ixx="1" ixy="0.0" ixz="0.0" iyy="1" iyz="0.0" izz="01"/>
    </inertial>
  </link> 

  <joint name="world_to_base" type="fixed">
    <origin rpy="0 0 0" xyz="0 0 0.1"/>
    <parent link="world"/>
    <child link="base_link"/>
  </joint>
  <joint name="slider" type="prismatic">
    <axis xyz="1 0 0"/>
    <origin xyz="0.0 0.0 0.1"/>
    <parent link="cuboid_y"/>
    <child link="cuboid"/>
    <limit effort="1000.0" lower="-50" upper="50" velocity="300"/>
    <dynamics damping="0.0" friction="0.0"/> <!-- Friction value set to 0.0 -->
  </joint>
    <joint name="slider_y" type="prismatic">
    <axis xyz="0 1 0"/>
    <origin xyz="0.0 0.0 0.1"/>
    <parent link="base_link"/>
    <child link="cuboid_y"/>
    <limit effort="1000.0" lower="-50" upper="50" velocity="300"/>
    <dynamics damping="0.0" friction="0.0"/> <!-- Friction value set to 0.0 -->
  </joint>

  <ros2_control name="GazeboSystem" type="system">
    <hardware>
      <plugin>gazebo_ros2_control/GazeboSystem</plugin>
    </hardware>
    <joint name="slider">
      <command_interface name="effort">
        <param name="min">-20</param>
        <param name="max">20</param>
      </command_interface>
      <state_interface name="position">
        <param name="initial_value">0</param>
      </state_interface>
      <state_interface name="velocity"/>
      <state_interface name="effort"/>
    </joint>

    <joint name="slider_y">
      <command_interface name="effort">
        <param name="min">-20</param>
        <param name="max">20</param>
      </command_interface>
      <state_interface name="position">
        <param name="initial_value">0</param>
      </state_interface>
      <state_interface name="velocity"/>
      <state_interface name="effort"/>
    </joint> 
  </ros2_control> 

  <gazebo reference="cuboid">
        <mu1>0.8</mu1>
        <mu2>0.8</mu2>
        <material>Gazebo/Green</material>
    </gazebo>

  <gazebo>
    <plugin filename="libgazebo_ros2_control.so" name="gazebo_ros2_control">
      <parameters>$(find gazebo_ros2_control_demos)/config/control_config.yaml</parameters>
    </plugin>
  </gazebo>
</robot>
